<mujoco model="elf2">
  <compiler angle="radian" autolimits="true"/>
  <default/>
  <asset>
    <mesh name="base_link" file="base_link.STL"/>
    <mesh name="waist_z_link" file="waist_z_link.STL"/>
    <mesh name="l_hip_z_link" file="l_hip_z_link.STL"/>
    <mesh name="l_hip_x_link" file="l_hip_x_link.STL"/>
    <mesh name="l_hip_y_link" file="l_hip_y_link.STL"/>
    <mesh name="l_knee_y_link" file="l_knee_y_link.STL"/>
    <mesh name="l_ankle_x_link" file="l_ankle_x_link.STL"/>
    <mesh name="r_hip_z_link" file="r_hip_z_link.STL"/>
    <mesh name="r_hip_x_link" file="r_hip_x_link.STL"/>
    <mesh name="r_hip_y_link" file="r_hip_y_link.STL"/>
    <mesh name="r_knee_y_link" file="r_knee_y_link.STL"/>
    <mesh name="r_ankle_x_link" file="r_ankle_x_link.STL"/>
    <mesh name="l_shld_y_link" file="l_shld_y_link.STL"/>
    <mesh name="l_shld_x_link" file="l_shld_x_link.STL"/>
    <mesh name="l_shld_z_link" file="l_shld_z_link.STL"/>
    <mesh name="l_elb_y_link" file="l_elb_y_link.STL"/>
    <mesh name="l_elb_z_link" file="l_elb_z_link.STL"/>
    <mesh name="r_shld_y_link" file="r_shld_y_link.STL"/>
    <mesh name="r_shld_x_link" file="r_shld_x_link.STL"/>
    <mesh name="r_shld_z_link" file="r_shld_z_link.STL"/>
    <mesh name="r_elb_y_link" file="r_elb_y_link.STL"/>
    <mesh name="r_elb_z_link" file="r_elb_z_link.STL"/>
  </asset>
  <worldbody>
    <body name="base_link" pos="0 0 0" gravcomp="0">
      <inertial pos="-0.002719 0.001928 0.003917" quat="0.99998 0.000694877 0.00586675 -0.00203064" mass="8.94844" diaginertia="0.187477 0.142271 0.0695066"/>
      <joint name="world_joint" type="free"/>
      <geom type="mesh" rgba="0.75294 0.75294 0.75294 1" mesh="base_link"/>
      <body name="waist_y_link" pos="0 0 -0.2087" gravcomp="0">
        <inertial pos="0 0 0" quat="0.5 0.5 -0.5 0.5" mass="0.0531674" diaginertia="1.819e-05 9.7e-06 9.7e-06"/>
        <joint name="waist_y_joint" pos="0 0 0" axis="0 1 0" range="-0.523 0.523"/>
        <body name="waist_x_link" pos="0 0 0" gravcomp="0">
          <inertial pos="-0.00448944 0 -0.0238919" quat="0 0.867095 0 0.498142" mass="0.21792" diaginertia="0.000150161 0.0001491 7.07387e-05"/>
          <joint name="waist_x_joint" pos="0 0 0" axis="1 0 0" range="-0.261 0.261"/>
          <body name="waist_z_link" pos="0 0 0" gravcomp="0">
            <inertial pos="0.00031142 0.00082403 -0.0822689" quat="0.496903 0.498782 -0.503063 0.50123" mass="3.12645" diaginertia="0.0229475 0.0215716 0.00322266"/>
            <joint name="waist_z_joint" pos="0 0 0" axis="0 0 1" range="-1.57 1.57"/>
            <geom type="mesh" rgba="0.752941 0.752941 0.752941 1" mesh="waist_z_link"/>
            <body name="l_hip_z_link" pos="0 0.1 -0.2175" gravcomp="0">
              <inertial pos="-0.0951743 -0.00029544 0.011577" quat="0.950348 -0.0165245 0.307379 -0.0456384" mass="1.26003" diaginertia="0.00318767 0.00299323 0.00121169"/>
              <joint name="l_hip_z_joint" pos="0 0 0" axis="0 0 1" range="-0.785 0.785"/>
              <geom type="mesh" rgba="0.752941 0.752941 0.752941 1" mesh="l_hip_z_link"/>
              <body name="l_hip_x_link" pos="0 0 0" gravcomp="0">
                <inertial pos="-0.00349545 -0.0501608 0.00015601" quat="0.578435 0.631575 0.35193 0.377717" mass="1.75826" diaginertia="0.00198223 0.00181137 0.00131094"/>
                <joint name="l_hip_x_joint" pos="0 0 0" axis="1 0 0" range="-0.523 0.785"/>
                <geom type="mesh" rgba="0.752941 0.752941 0.752941 1" mesh="l_hip_x_link"/>
                <body name="l_hip_y_link" pos="0 0 0" gravcomp="0">
                  <inertial pos="0.00237237 0.0240808 -0.0487449" quat="0.915126 -0.0824256 0.0170128 0.394286" mass="2.66296" diaginertia="0.0268551 0.0267772 0.00387364"/>
                  <joint name="l_hip_y_joint" pos="0 0 0" axis="0 1 0" range="-2 1"/>
                  <geom type="mesh" rgba="0.752941 0.752941 0.752941 1" mesh="l_hip_y_link"/>
                  <body name="l_knee_y_link" pos="0 0 -0.3" gravcomp="0">
                    <inertial pos="0.00711393 -0.00031499 -0.109778" quat="0.999281 -0.00839565 0.0304989 0.0209001" mass="1.63072" diaginertia="0.0104617 0.0101879 0.00137116"/>
                    <joint name="l_knee_y_joint" pos="0 0 0" axis="0 1 0" range="0 2.355"/>
                    <geom type="mesh" rgba="0.752941 0.752941 0.752941 1" mesh="l_knee_y_link"/>
                    <body name="l_ankle_y_link" pos="0 0 -0.3" gravcomp="0">
                      <inertial pos="0 0 -0.00046563" quat="0.5 0.5 -0.5 0.5" mass="0.0120696" diaginertia="3.01e-06 2.89e-06 3.4e-07"/>
                      <joint name="l_ankle_y_joint" pos="0 0 0" axis="0 1 0" range="-2 2"/>
                      <body name="l_ankle_x_link" pos="0 0 0" gravcomp="0">
                        <inertial pos="-0.00088171 0 -0.0224519" quat="0 0.710014 0 0.704188" mass="0.270642" diaginertia="0.000816706 0.00071745 0.000145444"/>
                        <joint name="l_ankle_x_joint" pos="0 0 0" axis="1 0 0" range="-0.349 0.349"/>
                        <geom type="mesh" rgba="0.752941 0.752941 0.752941 1" mesh="l_ankle_x_link"/>
                      </body>
                    </body>
                  </body>
                </body>
              </body>
            </body>
            <body name="r_hip_z_link" pos="0 -0.1 -0.2175" gravcomp="0">
              <inertial pos="-0.0951743 0.00029543 0.011577" quat="0.950348 0.0165245 0.307379 0.0456384" mass="1.26003" diaginertia="0.00318767 0.00299323 0.00121169"/>
              <joint name="r_hip_z_joint" pos="0 0 0" axis="0 0 1" range="-0.785 0.785"/>
              <geom type="mesh" rgba="0.752941 0.752941 0.752941 1" mesh="r_hip_z_link"/>
              <body name="r_hip_x_link" pos="0 0 0" gravcomp="0">
                <inertial pos="-0.00349545 0.0501608 0.000156" quat="0.377717 0.35193 0.631575 0.578435" mass="1.75826" diaginertia="0.00198223 0.00181137 0.00131094"/>
                <joint name="r_hip_x_joint" pos="0 0 0" axis="1 0 0" range="-0.785 0.523"/>
                <geom type="mesh" rgba="0.752941 0.752941 0.752941 1" mesh="r_hip_x_link"/>
                <body name="r_hip_y_link" pos="0 0 0" gravcomp="0">
                  <inertial pos="0.00237237 -0.0240808 -0.0487449" quat="0.394265 0.0170111 -0.0824261 0.915135" mass="2.66296" diaginertia="0.0268551 0.0267772 0.00387363"/>
                  <joint name="r_hip_y_joint" pos="0 0 0" axis="0 1 0" range="-2 1"/>
                  <geom type="mesh" rgba="0.752941 0.752941 0.752941 1" mesh="r_hip_y_link"/>
                  <body name="r_knee_y_link" pos="0 0 -0.3" gravcomp="0">
                    <inertial pos="0.00711396 0.00031502 -0.109778" quat="0.999281 0.00839515 0.0304983 -0.0208987" mass="1.63072" diaginertia="0.0104617 0.0101878 0.00137116"/>
                    <joint name="r_knee_y_joint" pos="0 0 0" axis="0 1 0" range="0 2.355"/>
                    <geom type="mesh" rgba="0.752941 0.752941 0.752941 1" mesh="r_knee_y_link"/>
                    <body name="r_ankle_y_link" pos="0 0 -0.3" gravcomp="0">
                      <inertial pos="0 0 -0.00046563" quat="0.5 0.5 -0.5 0.5" mass="0.0120696" diaginertia="3.01e-06 2.89e-06 3.4e-07"/>
                      <joint name="r_ankle_y_joint" pos="0 0 0" axis="0 1 0" range="-2 2"/>
                      <body name="r_ankle_x_link" pos="0 0 0" gravcomp="0">
                        <inertial pos="-0.00088171 0 -0.0224519" quat="0 0.710014 0 0.704188" mass="0.270642" diaginertia="0.000816706 0.00071745 0.000145444"/>
                        <joint name="r_ankle_x_joint" pos="0 0 0" axis="1 0 0" range="-0.349 0.349"/>
                        <geom type="mesh" rgba="0.752941 0.752941 0.752941 1" mesh="r_ankle_x_link"/>
                      </body>
                    </body>
                  </body>
                </body>
              </body>
            </body>
          </body>
        </body>
      </body>
      <body name="l_shld_y_link" pos="0 0.21705 0.09205" gravcomp="0">
        <inertial pos="0.00068297 -0.00449372 2.22e-06" quat="0.435933 0.557654 -0.43314 0.558009" mass="0.53805" diaginertia="0.00032312 0.000307497 0.000290513"/>
        <joint name="l_shld_y_joint" pos="0 0 0" axis="0 1 0" range="-2 2"/>
        <geom type="mesh" rgba="0.752941 0.752941 0.752941 1" mesh="l_shld_y_link"/>
        <body name="l_shld_x_link" pos="0 0 0" gravcomp="0">
          <inertial pos="-2.047e-05 5.316e-05 -0.0616265" quat="0.511019 0.489093 0.494385 0.505204" mass="0.488475" diaginertia="0.000337096 0.000288412 0.000271922"/>
          <joint name="l_shld_x_joint" pos="0 0 0" axis="1 0 0" range="-0.5 1.57"/>
          <geom type="mesh" rgba="0.752941 0.752941 0.752941 1" mesh="l_shld_x_link"/>
          <body name="l_shld_z_link" pos="0 0 0" gravcomp="0">
            <inertial pos="4.164e-05 0.00022669 -0.221278" quat="0.999947 0.000588453 -1.03341e-06 0.0102498" mass="0.593095" diaginertia="0.00136574 0.00133988 0.000303419"/>
            <joint name="l_shld_z_joint" pos="0 0 0" axis="0 0 1" range="-0.785 0.785"/>
            <geom type="mesh" rgba="0.752941 0.752941 0.752941 1" mesh="l_shld_z_link"/>
            <body name="l_elb_y_link" pos="0 0 -0.24" gravcomp="0">
              <inertial pos="5.192e-05 1.999e-05 -0.0856119" quat="0.999983 0.00544979 0.0018217 -0.000285656" mass="0.500057" diaginertia="0.000437132 0.000360437 0.000302651"/>
              <joint name="l_elb_y_joint" pos="0 0 0" axis="0 1 0" range="-2.355 0.5"/>
              <geom type="mesh" rgba="0.752941 0.752941 0.752941 1" mesh="l_elb_y_link"/>
              <body name="l_elb_z_link" pos="0 0 0" gravcomp="0">
                <inertial pos="1.97e-06 -1.756e-05 -0.182825" quat="1 0.00021844 2.91405e-05 -8.74832e-05" mass="0.134574" diaginertia="0.00040001 0.00039996 5.66199e-05"/>
                <joint name="l_elb_z_joint" pos="0 0 0" axis="0 0 1" range="-0.785 0.785"/>
                <geom type="mesh" rgba="0.752941 0.752941 0.752941 1" mesh="l_elb_z_link"/>
              </body>
            </body>
          </body>
        </body>
      </body>
      <body name="r_shld_y_link" pos="0 -0.21705 0.09205" gravcomp="0">
        <inertial pos="0.00068297 0.00449372 -2.22e-06" quat="0.558009 0.43314 -0.557654 0.435933" mass="0.53805" diaginertia="0.00032312 0.000307497 0.000290513"/>
        <joint name="r_shld_y_joint" pos="0 0 0" axis="0 1 0" range="-2 2"/>
        <geom type="mesh" rgba="1 1 1 1" mesh="r_shld_y_link"/>
        <body name="r_shld_x_link" pos="0 0 0" gravcomp="0">
          <inertial pos="2.047e-05 -5.316e-05 -0.0616265" quat="0.489093 0.511019 0.505204 0.494385" mass="0.488475" diaginertia="0.000337096 0.000288412 0.000271922"/>
          <joint name="r_shld_x_joint" pos="0 0 0" axis="1 0 0" range="-1.57 0.5"/>
          <geom type="mesh" rgba="0.752941 0.752941 0.752941 1" mesh="r_shld_x_link"/>
          <body name="r_shld_z_link" pos="0 0 0" gravcomp="0">
            <inertial pos="-4.164e-05 -0.00022669 -0.221278" quat="0.999947 -0.000588453 1.03341e-06 0.0102498" mass="0.593095" diaginertia="0.00136574 0.00133988 0.000303419"/>
            <joint name="r_shld_z_joint" pos="0 0 0" axis="0 0 1" range="-0.785 0.785"/>
            <geom type="mesh" rgba="0.752941 0.752941 0.752941 1" mesh="r_shld_z_link"/>
            <body name="r_elb_y_link" pos="0 0 -0.24" gravcomp="0">
              <inertial pos="-5.192e-05 -1.999e-05 -0.0856119" quat="0.999983 -0.00544979 -0.0018217 -0.000285656" mass="0.500057" diaginertia="0.000437132 0.000360437 0.000302651"/>
              <joint name="r_elb_y_joint" pos="0 0 0" axis="0 1 0" range="-2.355 0.5"/>
              <geom type="mesh" rgba="0.752941 0.752941 0.752941 1" mesh="r_elb_y_link"/>
              <body name="r_elb_z_link" pos="0 0 0" gravcomp="0">
                <inertial pos="-1.97e-06 1.756e-05 -0.182825" quat="1 -0.00021844 -2.91405e-05 -8.74832e-05" mass="0.134574" diaginertia="0.00040001 0.00039996 5.66199e-05"/>
                <joint name="r_elb_z_joint" pos="0 0 0" axis="0 0 1" range="-0.785 0.785"/>
                <geom type="mesh" rgba="0.752941 0.752941 0.752941 1" mesh="r_elb_z_link"/>
              </body>
            </body>
          </body>
        </body>
      </body>
    </body>
  </worldbody>
</mujoco>
